INFO:     127.0.0.1:42890 - "GET / HTTP/1.1" 401 Unauthorized
WARNING:  Invalid HTTP request received.
Traceback (most recent call last):
  File "/home/andreia/.local/lib/python3.8/site-packages/starlette/exceptions.py", line 71, in __call__
    await self.app(scope, receive, sender)
  File "/home/andreia/.local/lib/python3.8/site-packages/starlette/routing.py", line 580, in __call__
    await route.handle(scope, receive, send)
  File "/home/andreia/.local/lib/python3.8/site-packages/starlette/routing.py", line 241, in handle
    await self.app(scope, receive, send)
  File "/home/andreia/.local/lib/python3.8/site-packages/starlette/routing.py", line 52, in app
    response = await func(request)
  File "/home/andreia/.local/lib/python3.8/site-packages/fastapi/routing.py", line 191, in app
    solved_result = await solve_dependencies(
  File "/home/andreia/.local/lib/python3.8/site-packages/fastapi/dependencies/utils.py", line 550, in solve_dependencies
    solved = await run_in_threadpool(call, **sub_values)
  File "/home/andreia/.local/lib/python3.8/site-packages/starlette/concurrency.py", line 40, in run_in_threadpool
    return await loop.run_in_executor(None, func, *args)
  File "/usr/lib/python3.8/concurrent/futures/thread.py", line 57, in run
    result = self.fn(*self.args, **self.kwargs)
  File "main.py", line 117, in authenticate
    raise HTTPException(
fastapi.exceptions.HTTPException

During handling of the above exception, another exception occurred:

Traceback (most recent call last):
  File "/home/andreia/.local/lib/python3.8/site-packages/uvicorn/protocols/http/h11_impl.py", line 136, in handle_events
    event = self.conn.next_event()
  File "/home/andreia/.local/lib/python3.8/site-packages/h11/_connection.py", line 443, in next_event
    exc._reraise_as_remote_protocol_error()
  File "/home/andreia/.local/lib/python3.8/site-packages/h11/_util.py", line 76, in _reraise_as_remote_protocol_error
    raise self
  File "/home/andreia/.local/lib/python3.8/site-packages/h11/_connection.py", line 425, in next_event
    event = self._extract_next_receive_event()
  File "/home/andreia/.local/lib/python3.8/site-packages/h11/_connection.py", line 367, in _extract_next_receive_event
    event = self._reader(self._receive_buffer)
  File "/home/andreia/.local/lib/python3.8/site-packages/h11/_readers.py", line 71, in maybe_read_from_IDLE_client
    raise LocalProtocolError("no request line received")
h11._util.RemoteProtocolError: no request line received
